<?xml version="1.0"?>
<robot xmlns:xacro="http://www.ros.org/wiki/xacro" name="ball_tracker_robot">

  <!-- ========== MATERIALS ========== -->
  <material name="white">  <color rgba="1 1 1 1"/>        </material>
  <material name="blue">   <color rgba="0.2 0.2 1 1"/>    </material>
  <material name="black">  <color rgba="0 0 0 1"/>        </material>
  <material name="grey">   <color rgba="0.5 0.5 0.5 1"/> </material>

  <!-- ========== BASE LINK (rotation centre between drive wheels) ========== -->
  <link name="base_link"/>

  <!-- ========== CHASSIS ========== -->
  <joint name="chassis_joint" type="fixed">
    <parent link="base_link"/>
    <child  link="chassis"/>
    <origin xyz="-0.1 0 0"/>
  </joint>

  <link name="chassis">
    <visual>
      <origin xyz="0.15 0 0.075"/>
      <geometry><box size="0.30 0.25 0.10"/></geometry>
      <material name="white"/>
    </visual>
    <collision>
      <origin xyz="0.15 0 0.075"/>
      <geometry><box size="0.30 0.25 0.10"/></geometry>
    </collision>
    <inertial>
      <mass value="1.0"/>
      <origin xyz="0.15 0 0.075"/>
      <inertia ixx="1e-2" ixy="0" ixz="0" iyy="1e-2" iyz="0" izz="1e-2"/>
    </inertial>
  </link>

  <!-- ========== LEFT WHEEL ========== -->
  <joint name="left_wheel_joint" type="continuous">
    <parent link="base_link"/>
    <child  link="left_wheel"/>
    <origin xyz="0 0.15 0" rpy="-1.5708 0 0"/>
    <axis xyz="0 0 1"/>
  </joint>

  <link name="left_wheel">
    <visual>
      <geometry><cylinder length="0.04" radius="0.05"/></geometry>
      <material name="blue"/>
    </visual>
    <collision>
      <geometry><cylinder length="0.04" radius="0.05"/></geometry>
    </collision>
    <inertial>
      <mass value="0.1"/>
      <inertia ixx="1e-4" ixy="0" ixz="0" iyy="1e-4" iyz="0" izz="1e-4"/>
    </inertial>
  </link>

  <!-- ========== RIGHT WHEEL ========== -->
  <joint name="right_wheel_joint" type="continuous">
    <parent link="base_link"/>
    <child  link="right_wheel"/>
    <origin xyz="0 -0.15 0" rpy="1.5708 0 0"/>
    <axis xyz="0 0 -1"/>
  </joint>

  <link name="right_wheel">
    <visual>
      <geometry><cylinder length="0.04" radius="0.05"/></geometry>
      <material name="blue"/>
    </visual>
    <collision>
      <geometry><cylinder length="0.04" radius="0.05"/></geometry>
    </collision>
    <inertial>
      <mass value="0.1"/>
      <inertia ixx="1e-4" ixy="0" ixz="0" iyy="1e-4" iyz="0" izz="1e-4"/>
    </inertial>
  </link>

  <!-- ========== CASTER WHEEL ========== -->
  <joint name="caster_wheel_joint" type="fixed">
    <parent link="chassis"/>
    <child  link="caster_wheel"/>
    <origin xyz="0.24 0 0"/>
  </joint>

  <link name="caster_wheel">
    <visual>
      <geometry><sphere radius="0.025"/></geometry>
      <material name="black"/>
    </visual>
    <collision>
      <geometry><sphere radius="0.025"/></geometry>
    </collision>
    <inertial>
      <mass value="0.05"/>
      <inertia ixx="1e-5" ixy="0" ixz="0" iyy="1e-5" iyz="0" izz="1e-5"/>
    </inertial>
  </link>

  <!-- ========== CAMERA MOUNT ========== -->
  <joint name="camera_joint" type="fixed">
    <parent link="chassis"/>
    <child  link="camera_link"/>
    <origin xyz="0.28 0 0.13"/>
  </joint>

  <link name="camera_link">
    <visual>
      <geometry><box size="0.03 0.06 0.03"/></geometry>
      <material name="grey"/>
    </visual>
    <collision>
      <geometry><box size="0.03 0.06 0.03"/></geometry>
    </collision>
    <inertial>
      <mass value="0.01"/>
      <inertia ixx="1e-6" ixy="0" ixz="0" iyy="1e-6" iyz="0" izz="1e-6"/>
    </inertial>
  </link>

  <!-- Camera optical frame (Z forward, X right, Y down — ROS convention) -->
  <joint name="camera_optical_joint" type="fixed">
    <parent link="camera_link"/>
    <child  link="camera_optical_link"/>
    <origin rpy="-1.5708 0 -1.5708"/>
  </joint>

  <link name="camera_optical_link"/>

  <!-- ========== GAZEBO: COLOURS ========== -->
  <gazebo reference="chassis">      <material>Gazebo/White</material> </gazebo>
  <gazebo reference="left_wheel">   <material>Gazebo/Blue</material>  </gazebo>
  <gazebo reference="right_wheel">  <material>Gazebo/Blue</material>  </gazebo>
  <gazebo reference="caster_wheel">
    <material>Gazebo/Black</material>
    <mu1 value="0.001"/>
    <mu2 value="0.001"/>
  </gazebo>
  <gazebo reference="camera_link">  <material>Gazebo/Grey</material>  </gazebo>

  <!-- ========== GAZEBO: DIFF-DRIVE PLUGIN ========== -->
  <gazebo>
    <plugin name="diff_drive" filename="libgazebo_ros_diff_drive.so">
      <left_joint>left_wheel_joint</left_joint>
      <right_joint>right_wheel_joint</right_joint>
      <wheel_separation>0.30</wheel_separation>
      <wheel_diameter>0.10</wheel_diameter>
      <max_wheel_torque>20</max_wheel_torque>
      <max_wheel_acceleration>1.0</max_wheel_acceleration>
      <odometry_frame>odom</odometry_frame>
      <robot_base_frame>base_link</robot_base_frame>
      <publish_odom>true</publish_odom>
      <publish_odom_tf>true</publish_odom_tf>
      <publish_wheel_tf>true</publish_wheel_tf>
    </plugin>
  </gazebo>

  <!-- ========== GAZEBO: CAMERA PLUGIN ========== -->
  <gazebo reference="camera_link">
    <sensor type="camera" name="camera">
      <update_rate>10</update_rate>
      <camera name="head">
        <horizontal_fov>1.3962634</horizontal_fov>
        <image>
          <width>320</width>
          <height>240</height>
          <format>R8G8B8</format>
        </image>
        <clip>
          <near>0.02</near>
          <far>20</far>
        </clip>
      </camera>
      <plugin name="camera_controller" filename="libgazebo_ros_camera.so">
        <frame_name>camera_optical_link</frame_name>
        <min_depth>0.1</min_depth>
        <max_depth>20.0</max_depth>
      </plugin>
    </sensor>
  </gazebo>

</robot>
